[INFO] 2025-05-21 10:32:38,444 django.utils.autoreload - Watching for file changes with StatReloader
[WARNING] 2025-05-21 10:35:00,141 django.request - Not Found: /api/users/
[WARNING] 2025-05-21 10:43:37,300 django.request - Bad Request: /api/users/register/
[INFO] 2025-05-21 10:50:49,410 django.utils.autoreload - C:\Users\kone\Documents\socisarl\scrum\config\settings\base.py changed, reloading.
[INFO] 2025-05-21 10:52:38,520 django.utils.autoreload - Watching for file changes with StatReloader
[INFO] 2025-05-21 10:53:03,273 django.utils.autoreload - C:\Users\kone\Documents\socisarl\scrum\apps\users\views.py changed, reloading.
[INFO] 2025-05-21 10:53:14,069 django.utils.autoreload - Watching for file changes with StatReloader
[INFO] 2025-05-21 11:50:17,113 django.utils.autoreload - C:\Users\kone\Documents\socisarl\scrum\config\settings\base.py changed, reloading.
[INFO] 2025-05-21 11:51:24,817 django.utils.autoreload - Watching for file changes with StatReloader
[INFO] 2025-05-21 11:55:13,184 django.utils.autoreload - C:\Users\kone\Documents\socisarl\scrum\config\settings\base.py changed, reloading.
[INFO] 2025-05-21 11:56:03,573 django.utils.autoreload - Watching for file changes with StatReloader
[INFO] 2025-05-21 12:52:02,286 django.utils.autoreload - C:\Users\kone\Documents\socisarl\scrum\apps\users\views.py changed, reloading.
[INFO] 2025-05-21 12:52:26,606 django.utils.autoreload - Watching for file changes with StatReloader
[INFO] 2025-05-21 12:52:36,853 django.utils.autoreload - C:\Users\kone\Documents\socisarl\scrum\apps\users\views.py changed, reloading.
[INFO] 2025-05-21 12:52:49,754 django.utils.autoreload - Watching for file changes with StatReloader
[INFO] 2025-05-21 12:53:03,953 django.utils.autoreload - C:\Users\kone\Documents\socisarl\scrum\apps\users\views.py changed, reloading.
[INFO] 2025-05-21 12:53:15,646 django.utils.autoreload - Watching for file changes with StatReloader
[INFO] 2025-05-21 12:57:08,222 django.utils.autoreload - C:\Users\kone\Documents\socisarl\scrum\apps\users\views.py changed, reloading.
[INFO] 2025-05-21 12:57:17,438 django.utils.autoreload - Watching for file changes with StatReloader
[DEBUG] 2025-05-21 12:57:24,887 urllib3.connectionpool - Starting new HTTPS connection (1): o518522.ingest.us.sentry.io:443
[ERROR] 2025-05-21 12:57:25,456 django.request - Internal Server Error: /api/users/register/
Traceback (most recent call last):
  File "C:\Users\kone\Documents\socisarl\scrum\apps\users\views.py", line 21, in create
    self.logger.info(f"[REGISTER] Tentative de création: {request.data}")
    ^^^^^^^^^^^
AttributeError: 'RegisterView' object has no attribute 'logger'

During handling of the above exception, another exception occurred:

Traceback (most recent call last):
  File "C:\Users\kone\Documents\socisarl\scrum\scrumenv\Lib\site-packages\django\core\handlers\exception.py", line 55, in inner
    response = get_response(request)
               ^^^^^^^^^^^^^^^^^^^^^
  File "C:\Users\kone\Documents\socisarl\scrum\scrumenv\Lib\site-packages\django\core\handlers\base.py", line 197, in _get_response
    response = wrapped_callback(request, *callback_args, **callback_kwargs)
               ^^^^^^^^^^^^^^^^^^^^^^^^^^^^^^^^^^^^^^^^^^^^^^^^^^^^^^^^^^^^
  File "C:\Users\kone\Documents\socisarl\scrum\scrumenv\Lib\site-packages\sentry_sdk\integrations\django\views.py", line 94, in sentry_wrapped_callback
    return callback(request, *args, **kwargs)
           ^^^^^^^^^^^^^^^^^^^^^^^^^^^^^^^^^^
  File "C:\Users\kone\Documents\socisarl\scrum\scrumenv\Lib\site-packages\django\views\decorators\csrf.py", line 65, in _view_wrapper
    return view_func(request, *args, **kwargs)
           ^^^^^^^^^^^^^^^^^^^^^^^^^^^^^^^^^^^
  File "C:\Users\kone\Documents\socisarl\scrum\scrumenv\Lib\site-packages\django\views\generic\base.py", line 104, in view
    return self.dispatch(request, *args, **kwargs)
           ^^^^^^^^^^^^^^^^^^^^^^^^^^^^^^^^^^^^^^^
  File "C:\Users\kone\Documents\socisarl\scrum\scrumenv\Lib\site-packages\rest_framework\views.py", line 515, in dispatch
    response = self.handle_exception(exc)
               ^^^^^^^^^^^^^^^^^^^^^^^^^^
  File "C:\Users\kone\Documents\socisarl\scrum\scrumenv\Lib\site-packages\rest_framework\views.py", line 475, in handle_exception
    self.raise_uncaught_exception(exc)
  File "C:\Users\kone\Documents\socisarl\scrum\scrumenv\Lib\site-packages\rest_framework\views.py", line 486, in raise_uncaught_exception
    raise exc
  File "C:\Users\kone\Documents\socisarl\scrum\scrumenv\Lib\site-packages\rest_framework\views.py", line 512, in dispatch
    response = handler(request, *args, **kwargs)
               ^^^^^^^^^^^^^^^^^^^^^^^^^^^^^^^^^
  File "C:\Users\kone\Documents\socisarl\scrum\scrumenv\Lib\site-packages\rest_framework\generics.py", line 194, in post
    return self.create(request, *args, **kwargs)
           ^^^^^^^^^^^^^^^^^^^^^^^^^^^^^^^^^^^^^
  File "C:\Users\kone\Documents\socisarl\scrum\apps\users\views.py", line 26, in create
    self.logger.error(f"[REGISTER ERROR] Erreur: {str(e)}", exc_info=True)
    ^^^^^^^^^^^
AttributeError: 'RegisterView' object has no attribute 'logger'
[DEBUG] 2025-05-21 12:57:28,270 urllib3.connectionpool - https://o518522.ingest.us.sentry.io:443 "POST /api/4509357399539712/envelope/ HTTP/1.1" 200 0
[DEBUG] 2025-05-21 12:57:28,444 urllib3.connectionpool - https://o518522.ingest.us.sentry.io:443 "POST /api/4509357399539712/envelope/ HTTP/1.1" 200 0
[ERROR] 2025-05-21 12:58:17,683 django.request - Internal Server Error: /api/users/register/
Traceback (most recent call last):
  File "C:\Users\kone\Documents\socisarl\scrum\apps\users\views.py", line 21, in create
    self.logger.info(f"[REGISTER] Tentative de création: {request.data}")
    ^^^^^^^^^^^
AttributeError: 'RegisterView' object has no attribute 'logger'

During handling of the above exception, another exception occurred:

Traceback (most recent call last):
  File "C:\Users\kone\Documents\socisarl\scrum\scrumenv\Lib\site-packages\django\core\handlers\exception.py", line 55, in inner
    response = get_response(request)
               ^^^^^^^^^^^^^^^^^^^^^
  File "C:\Users\kone\Documents\socisarl\scrum\scrumenv\Lib\site-packages\django\core\handlers\base.py", line 197, in _get_response
    response = wrapped_callback(request, *callback_args, **callback_kwargs)
               ^^^^^^^^^^^^^^^^^^^^^^^^^^^^^^^^^^^^^^^^^^^^^^^^^^^^^^^^^^^^
  File "C:\Users\kone\Documents\socisarl\scrum\scrumenv\Lib\site-packages\sentry_sdk\integrations\django\views.py", line 94, in sentry_wrapped_callback
    return callback(request, *args, **kwargs)
           ^^^^^^^^^^^^^^^^^^^^^^^^^^^^^^^^^^
  File "C:\Users\kone\Documents\socisarl\scrum\scrumenv\Lib\site-packages\django\views\decorators\csrf.py", line 65, in _view_wrapper
    return view_func(request, *args, **kwargs)
           ^^^^^^^^^^^^^^^^^^^^^^^^^^^^^^^^^^^
  File "C:\Users\kone\Documents\socisarl\scrum\scrumenv\Lib\site-packages\django\views\generic\base.py", line 104, in view
    return self.dispatch(request, *args, **kwargs)
           ^^^^^^^^^^^^^^^^^^^^^^^^^^^^^^^^^^^^^^^
  File "C:\Users\kone\Documents\socisarl\scrum\scrumenv\Lib\site-packages\rest_framework\views.py", line 515, in dispatch
    response = self.handle_exception(exc)
               ^^^^^^^^^^^^^^^^^^^^^^^^^^
  File "C:\Users\kone\Documents\socisarl\scrum\scrumenv\Lib\site-packages\rest_framework\views.py", line 475, in handle_exception
    self.raise_uncaught_exception(exc)
  File "C:\Users\kone\Documents\socisarl\scrum\scrumenv\Lib\site-packages\rest_framework\views.py", line 486, in raise_uncaught_exception
    raise exc
  File "C:\Users\kone\Documents\socisarl\scrum\scrumenv\Lib\site-packages\rest_framework\views.py", line 512, in dispatch
    response = handler(request, *args, **kwargs)
               ^^^^^^^^^^^^^^^^^^^^^^^^^^^^^^^^^
  File "C:\Users\kone\Documents\socisarl\scrum\scrumenv\Lib\site-packages\rest_framework\generics.py", line 194, in post
    return self.create(request, *args, **kwargs)
           ^^^^^^^^^^^^^^^^^^^^^^^^^^^^^^^^^^^^^
  File "C:\Users\kone\Documents\socisarl\scrum\apps\users\views.py", line 26, in create
    self.logger.error(f"[REGISTER ERROR] Erreur: {str(e)}", exc_info=True)
    ^^^^^^^^^^^
AttributeError: 'RegisterView' object has no attribute 'logger'
[DEBUG] 2025-05-21 12:58:17,770 urllib3.connectionpool - https://o518522.ingest.us.sentry.io:443 "POST /api/4509357399539712/envelope/ HTTP/1.1" 200 0
[DEBUG] 2025-05-21 12:58:18,035 urllib3.connectionpool - https://o518522.ingest.us.sentry.io:443 "POST /api/4509357399539712/envelope/ HTTP/1.1" 200 0
[DEBUG] 2025-05-21 12:58:25,961 urllib3.connectionpool - https://o518522.ingest.us.sentry.io:443 "POST /api/4509357399539712/envelope/ HTTP/1.1" 200 0
[INFO] 2025-05-21 12:59:08,579 django.utils.autoreload - Watching for file changes with StatReloader
[DEBUG] 2025-05-21 12:59:33,697 urllib3.connectionpool - Starting new HTTPS connection (1): o518522.ingest.us.sentry.io:443
[ERROR] 2025-05-21 12:59:33,901 django.request - Internal Server Error: /api/users/register/
Traceback (most recent call last):
  File "C:\Users\kone\Documents\socisarl\scrum\apps\users\views.py", line 21, in create
    self.logger.info(f"[REGISTER] Tentative de création: {request.data}")
    ^^^^^^^^^^^
AttributeError: 'RegisterView' object has no attribute 'logger'

During handling of the above exception, another exception occurred:

Traceback (most recent call last):
  File "C:\Users\kone\Documents\socisarl\scrum\scrumenv\Lib\site-packages\django\core\handlers\exception.py", line 55, in inner
    response = get_response(request)
               ^^^^^^^^^^^^^^^^^^^^^
  File "C:\Users\kone\Documents\socisarl\scrum\scrumenv\Lib\site-packages\django\core\handlers\base.py", line 197, in _get_response
    response = wrapped_callback(request, *callback_args, **callback_kwargs)
               ^^^^^^^^^^^^^^^^^^^^^^^^^^^^^^^^^^^^^^^^^^^^^^^^^^^^^^^^^^^^
  File "C:\Users\kone\Documents\socisarl\scrum\scrumenv\Lib\site-packages\sentry_sdk\integrations\django\views.py", line 94, in sentry_wrapped_callback
    return callback(request, *args, **kwargs)
           ^^^^^^^^^^^^^^^^^^^^^^^^^^^^^^^^^^
  File "C:\Users\kone\Documents\socisarl\scrum\scrumenv\Lib\site-packages\django\views\decorators\csrf.py", line 65, in _view_wrapper
    return view_func(request, *args, **kwargs)
           ^^^^^^^^^^^^^^^^^^^^^^^^^^^^^^^^^^^
  File "C:\Users\kone\Documents\socisarl\scrum\scrumenv\Lib\site-packages\django\views\generic\base.py", line 104, in view
    return self.dispatch(request, *args, **kwargs)
           ^^^^^^^^^^^^^^^^^^^^^^^^^^^^^^^^^^^^^^^
  File "C:\Users\kone\Documents\socisarl\scrum\scrumenv\Lib\site-packages\rest_framework\views.py", line 515, in dispatch
    response = self.handle_exception(exc)
               ^^^^^^^^^^^^^^^^^^^^^^^^^^
  File "C:\Users\kone\Documents\socisarl\scrum\scrumenv\Lib\site-packages\rest_framework\views.py", line 475, in handle_exception
    self.raise_uncaught_exception(exc)
  File "C:\Users\kone\Documents\socisarl\scrum\scrumenv\Lib\site-packages\rest_framework\views.py", line 486, in raise_uncaught_exception
    raise exc
  File "C:\Users\kone\Documents\socisarl\scrum\scrumenv\Lib\site-packages\rest_framework\views.py", line 512, in dispatch
    response = handler(request, *args, **kwargs)
               ^^^^^^^^^^^^^^^^^^^^^^^^^^^^^^^^^
  File "C:\Users\kone\Documents\socisarl\scrum\scrumenv\Lib\site-packages\rest_framework\generics.py", line 194, in post
    return self.create(request, *args, **kwargs)
           ^^^^^^^^^^^^^^^^^^^^^^^^^^^^^^^^^^^^^
  File "C:\Users\kone\Documents\socisarl\scrum\apps\users\views.py", line 26, in create
    self.logger.error(f"[REGISTER ERROR] Erreur: {str(e)}", exc_info=True)
    ^^^^^^^^^^^
AttributeError: 'RegisterView' object has no attribute 'logger'
[DEBUG] 2025-05-21 12:59:39,817 urllib3.connectionpool - https://o518522.ingest.us.sentry.io:443 "POST /api/4509357399539712/envelope/ HTTP/1.1" 200 0
[DEBUG] 2025-05-21 12:59:40,002 urllib3.connectionpool - https://o518522.ingest.us.sentry.io:443 "POST /api/4509357399539712/envelope/ HTTP/1.1" 200 0
[DEBUG] 2025-05-21 13:00:34,946 urllib3.connectionpool - https://o518522.ingest.us.sentry.io:443 "POST /api/4509357399539712/envelope/ HTTP/1.1" 200 0
[INFO] 2025-05-21 13:02:30,335 django.utils.autoreload - C:\Users\kone\Documents\socisarl\scrum\apps\users\views.py changed, reloading.
[INFO] 2025-05-21 13:02:42,690 django.utils.autoreload - Watching for file changes with StatReloader
[DEBUG] 2025-05-21 13:06:08,331 urllib3.connectionpool - Starting new HTTPS connection (1): o518522.ingest.us.sentry.io:443
[ERROR] 2025-05-21 13:06:08,641 django.request - Internal Server Error: /api/users/register/
Traceback (most recent call last):
  File "C:\Users\kone\Documents\socisarl\scrum\apps\users\views.py", line 23, in create
    self.logger.info(f"[REGISTER] Tentative de création: {request.data}")
    ^^^^^^^^^^^
AttributeError: 'RegisterView' object has no attribute 'logger'

During handling of the above exception, another exception occurred:

Traceback (most recent call last):
  File "C:\Users\kone\Documents\socisarl\scrum\scrumenv\Lib\site-packages\django\core\handlers\exception.py", line 55, in inner
    response = get_response(request)
               ^^^^^^^^^^^^^^^^^^^^^
  File "C:\Users\kone\Documents\socisarl\scrum\scrumenv\Lib\site-packages\django\core\handlers\base.py", line 197, in _get_response
    response = wrapped_callback(request, *callback_args, **callback_kwargs)
               ^^^^^^^^^^^^^^^^^^^^^^^^^^^^^^^^^^^^^^^^^^^^^^^^^^^^^^^^^^^^
  File "C:\Users\kone\Documents\socisarl\scrum\scrumenv\Lib\site-packages\sentry_sdk\integrations\django\views.py", line 94, in sentry_wrapped_callback
    return callback(request, *args, **kwargs)
           ^^^^^^^^^^^^^^^^^^^^^^^^^^^^^^^^^^
  File "C:\Users\kone\Documents\socisarl\scrum\scrumenv\Lib\site-packages\django\views\decorators\csrf.py", line 65, in _view_wrapper
    return view_func(request, *args, **kwargs)
           ^^^^^^^^^^^^^^^^^^^^^^^^^^^^^^^^^^^
  File "C:\Users\kone\Documents\socisarl\scrum\scrumenv\Lib\site-packages\django\views\generic\base.py", line 104, in view
    return self.dispatch(request, *args, **kwargs)
           ^^^^^^^^^^^^^^^^^^^^^^^^^^^^^^^^^^^^^^^
  File "C:\Users\kone\Documents\socisarl\scrum\scrumenv\Lib\site-packages\rest_framework\views.py", line 515, in dispatch
    response = self.handle_exception(exc)
               ^^^^^^^^^^^^^^^^^^^^^^^^^^
  File "C:\Users\kone\Documents\socisarl\scrum\scrumenv\Lib\site-packages\rest_framework\views.py", line 475, in handle_exception
    self.raise_uncaught_exception(exc)
  File "C:\Users\kone\Documents\socisarl\scrum\scrumenv\Lib\site-packages\rest_framework\views.py", line 486, in raise_uncaught_exception
    raise exc
  File "C:\Users\kone\Documents\socisarl\scrum\scrumenv\Lib\site-packages\rest_framework\views.py", line 512, in dispatch
    response = handler(request, *args, **kwargs)
               ^^^^^^^^^^^^^^^^^^^^^^^^^^^^^^^^^
  File "C:\Users\kone\Documents\socisarl\scrum\scrumenv\Lib\site-packages\rest_framework\generics.py", line 194, in post
    return self.create(request, *args, **kwargs)
           ^^^^^^^^^^^^^^^^^^^^^^^^^^^^^^^^^^^^^
  File "C:\Users\kone\Documents\socisarl\scrum\apps\users\views.py", line 28, in create
    self.logger.error(f"[REGISTER ERROR] Erreur: {str(e)}", exc_info=True)
    ^^^^^^^^^^^
AttributeError: 'RegisterView' object has no attribute 'logger'
[DEBUG] 2025-05-21 13:06:29,977 urllib3.util.retry - Incremented Retry for (url='/api/4509357399539712/envelope/'): Retry(total=2, connect=None, read=None, redirect=None, status=None)
[WARNING] 2025-05-21 13:06:29,988 urllib3.connectionpool - Retrying (Retry(total=2, connect=None, read=None, redirect=None, status=None)) after connection broken by 'ConnectTimeoutError(<urllib3.connection.HTTPSConnection object at 0x000001DE47ABCE60>, 'Connection to o518522.ingest.us.sentry.io timed out. (connect timeout=30)')': /api/4509357399539712/envelope/
[DEBUG] 2025-05-21 13:06:30,033 urllib3.connectionpool - Starting new HTTPS connection (2): o518522.ingest.us.sentry.io:443
[DEBUG] 2025-05-21 13:06:51,470 urllib3.util.retry - Incremented Retry for (url='/api/4509357399539712/envelope/'): Retry(total=1, connect=None, read=None, redirect=None, status=None)
[WARNING] 2025-05-21 13:06:51,470 urllib3.connectionpool - Retrying (Retry(total=1, connect=None, read=None, redirect=None, status=None)) after connection broken by 'ConnectTimeoutError(<urllib3.connection.HTTPSConnection object at 0x000001DE474EF920>, 'Connection to o518522.ingest.us.sentry.io timed out. (connect timeout=30)')': /api/4509357399539712/envelope/
[DEBUG] 2025-05-21 13:06:51,487 urllib3.connectionpool - Starting new HTTPS connection (3): o518522.ingest.us.sentry.io:443
[DEBUG] 2025-05-21 13:07:12,562 urllib3.util.retry - Incremented Retry for (url='/api/4509357399539712/envelope/'): Retry(total=0, connect=None, read=None, redirect=None, status=None)
[WARNING] 2025-05-21 13:07:12,564 urllib3.connectionpool - Retrying (Retry(total=0, connect=None, read=None, redirect=None, status=None)) after connection broken by 'ConnectTimeoutError(<urllib3.connection.HTTPSConnection object at 0x000001DE4748AE10>, 'Connection to o518522.ingest.us.sentry.io timed out. (connect timeout=30)')': /api/4509357399539712/envelope/
[DEBUG] 2025-05-21 13:07:12,636 urllib3.connectionpool - Starting new HTTPS connection (4): o518522.ingest.us.sentry.io:443
[DEBUG] 2025-05-21 13:07:33,700 urllib3.connectionpool - Starting new HTTPS connection (5): o518522.ingest.us.sentry.io:443
[DEBUG] 2025-05-21 13:07:54,761 urllib3.util.retry - Incremented Retry for (url='/api/4509357399539712/envelope/'): Retry(total=2, connect=None, read=None, redirect=None, status=None)
[WARNING] 2025-05-21 13:07:54,761 urllib3.connectionpool - Retrying (Retry(total=2, connect=None, read=None, redirect=None, status=None)) after connection broken by 'ConnectTimeoutError(<urllib3.connection.HTTPSConnection object at 0x000001DE47AEFF20>, 'Connection to o518522.ingest.us.sentry.io timed out. (connect timeout=30)')': /api/4509357399539712/envelope/
[DEBUG] 2025-05-21 13:07:54,761 urllib3.connectionpool - Starting new HTTPS connection (6): o518522.ingest.us.sentry.io:443
[DEBUG] 2025-05-21 13:08:15,825 urllib3.util.retry - Incremented Retry for (url='/api/4509357399539712/envelope/'): Retry(total=1, connect=None, read=None, redirect=None, status=None)
[WARNING] 2025-05-21 13:08:15,825 urllib3.connectionpool - Retrying (Retry(total=1, connect=None, read=None, redirect=None, status=None)) after connection broken by 'ConnectTimeoutError(<urllib3.connection.HTTPSConnection object at 0x000001DE47AE1100>, 'Connection to o518522.ingest.us.sentry.io timed out. (connect timeout=30)')': /api/4509357399539712/envelope/
[DEBUG] 2025-05-21 13:08:15,828 urllib3.connectionpool - Starting new HTTPS connection (7): o518522.ingest.us.sentry.io:443
[DEBUG] 2025-05-21 13:08:37,027 urllib3.util.retry - Incremented Retry for (url='/api/4509357399539712/envelope/'): Retry(total=0, connect=None, read=None, redirect=None, status=None)
[WARNING] 2025-05-21 13:08:37,027 urllib3.connectionpool - Retrying (Retry(total=0, connect=None, read=None, redirect=None, status=None)) after connection broken by 'ConnectTimeoutError(<urllib3.connection.HTTPSConnection object at 0x000001DE47AE2CF0>, 'Connection to o518522.ingest.us.sentry.io timed out. (connect timeout=30)')': /api/4509357399539712/envelope/
[DEBUG] 2025-05-21 13:08:37,027 urllib3.connectionpool - Starting new HTTPS connection (8): o518522.ingest.us.sentry.io:443
[DEBUG] 2025-05-21 13:08:58,156 urllib3.connectionpool - Starting new HTTPS connection (9): o518522.ingest.us.sentry.io:443
[DEBUG] 2025-05-21 13:09:19,291 urllib3.util.retry - Incremented Retry for (url='/api/4509357399539712/envelope/'): Retry(total=2, connect=None, read=None, redirect=None, status=None)
[WARNING] 2025-05-21 13:09:19,291 urllib3.connectionpool - Retrying (Retry(total=2, connect=None, read=None, redirect=None, status=None)) after connection broken by 'ConnectTimeoutError(<urllib3.connection.HTTPSConnection object at 0x000001DE47AE15B0>, 'Connection to o518522.ingest.us.sentry.io timed out. (connect timeout=30)')': /api/4509357399539712/envelope/
[DEBUG] 2025-05-21 13:09:19,291 urllib3.connectionpool - Starting new HTTPS connection (10): o518522.ingest.us.sentry.io:443
[DEBUG] 2025-05-21 13:09:40,492 urllib3.util.retry - Incremented Retry for (url='/api/4509357399539712/envelope/'): Retry(total=1, connect=None, read=None, redirect=None, status=None)
[WARNING] 2025-05-21 13:09:40,492 urllib3.connectionpool - Retrying (Retry(total=1, connect=None, read=None, redirect=None, status=None)) after connection broken by 'ConnectTimeoutError(<urllib3.connection.HTTPSConnection object at 0x000001DE47AE1160>, 'Connection to o518522.ingest.us.sentry.io timed out. (connect timeout=30)')': /api/4509357399539712/envelope/
[DEBUG] 2025-05-21 13:09:40,492 urllib3.connectionpool - Starting new HTTPS connection (11): o518522.ingest.us.sentry.io:443
[DEBUG] 2025-05-21 13:10:01,717 urllib3.util.retry - Incremented Retry for (url='/api/4509357399539712/envelope/'): Retry(total=0, connect=None, read=None, redirect=None, status=None)
[WARNING] 2025-05-21 13:10:01,717 urllib3.connectionpool - Retrying (Retry(total=0, connect=None, read=None, redirect=None, status=None)) after connection broken by 'ConnectTimeoutError(<urllib3.connection.HTTPSConnection object at 0x000001DE47AE2180>, 'Connection to o518522.ingest.us.sentry.io timed out. (connect timeout=30)')': /api/4509357399539712/envelope/
[DEBUG] 2025-05-21 13:10:01,717 urllib3.connectionpool - Starting new HTTPS connection (12): o518522.ingest.us.sentry.io:443
[INFO] 2025-05-21 13:17:06,793 django.utils.autoreload - C:\Users\kone\Documents\socisarl\scrum\apps\users\views.py changed, reloading.
[DEBUG] 2025-05-21 13:17:07,025 urllib3.connectionpool - Starting new HTTPS connection (13): o518522.ingest.us.sentry.io:443
[INFO] 2025-05-21 13:17:14,000 django.utils.autoreload - Watching for file changes with StatReloader
[DEBUG] 2025-05-21 13:17:14,935 urllib3.connectionpool - Starting new HTTPS connection (1): o518522.ingest.us.sentry.io:443
[DEBUG] 2025-05-21 13:17:21,048 urllib3.connectionpool - https://o518522.ingest.us.sentry.io:443 "POST /api/4509357399539712/envelope/ HTTP/1.1" 200 0
[INFO] 2025-05-21 13:17:53,200 django.utils.autoreload - C:\Users\kone\Documents\socisarl\scrum\apps\users\views.py changed, reloading.
[INFO] 2025-05-21 13:18:01,513 django.utils.autoreload - Watching for file changes with StatReloader
[INFO] 2025-05-21 13:18:18,779 django - [REGISTER] Tentative de création: {'username': 'aminad', 'email': 'aninad@yopmail.com', 'password': 'test1234', 'role': 'product_owner'}
[INFO] 2025-05-21 13:18:21,813 django - [REGISTER SUCCESS] Utilisateur créé: {'id': 6, 'username': 'Aminad', 'email': 'aninad@yopmail.com', 'role': 'product_owner'}
[DEBUG] 2025-05-21 13:18:21,871 urllib3.connectionpool - Starting new HTTPS connection (1): o518522.ingest.us.sentry.io:443
[DEBUG] 2025-05-21 13:18:23,720 urllib3.connectionpool - https://o518522.ingest.us.sentry.io:443 "POST /api/4509357399539712/envelope/ HTTP/1.1" 200 0
[DEBUG] 2025-05-21 13:19:22,227 urllib3.connectionpool - https://o518522.ingest.us.sentry.io:443 "POST /api/4509357399539712/envelope/ HTTP/1.1" 200 0
[INFO] 2025-05-21 13:54:51,116 django - [REGISTER] Tentative de création: {'username': 'aminad', 'email': 'aninad@yopmail.com', 'password': 'test1234', 'role': 'product_owner'}
[ERROR] 2025-05-21 13:54:51,153 django - [REGISTER ERROR] Erreur: {'username': [ErrorDetail(string='A user with that username already exists.', code='unique')], 'email': [ErrorDetail(string='user with this email already exists.', code='unique')]}
Traceback (most recent call last):
  File "C:\Users\kone\Documents\socisarl\scrum\apps\users\views.py", line 24, in create
    response = super().create(request, *args, **kwargs)
               ^^^^^^^^^^^^^^^^^^^^^^^^^^^^^^^^^^^^^^^^
  File "C:\Users\kone\Documents\socisarl\scrum\scrumenv\Lib\site-packages\rest_framework\mixins.py", line 18, in create
    serializer.is_valid(raise_exception=True)
  File "C:\Users\kone\Documents\socisarl\scrum\scrumenv\Lib\site-packages\rest_framework\serializers.py", line 233, in is_valid
    raise ValidationError(self.errors)
rest_framework.exceptions.ValidationError: {'username': [ErrorDetail(string='A user with that username already exists.', code='unique')], 'email': [ErrorDetail(string='user with this email already exists.', code='unique')]}
[DEBUG] 2025-05-21 13:54:51,536 urllib3.connectionpool - Resetting dropped connection: o518522.ingest.us.sentry.io
[ERROR] 2025-05-21 13:54:51,553 django.request - Internal Server Error: /api/users/register/
[DEBUG] 2025-05-21 13:54:53,994 urllib3.connectionpool - https://o518522.ingest.us.sentry.io:443 "POST /api/4509357399539712/envelope/ HTTP/1.1" 200 0
[DEBUG] 2025-05-21 13:54:54,169 urllib3.connectionpool - https://o518522.ingest.us.sentry.io:443 "POST /api/4509357399539712/envelope/ HTTP/1.1" 200 0
[DEBUG] 2025-05-21 13:55:23,130 urllib3.connectionpool - https://o518522.ingest.us.sentry.io:443 "POST /api/4509357399539712/envelope/ HTTP/1.1" 200 0
[INFO] 2025-05-21 13:55:49,796 django - [REGISTER] Tentative de création: {'username': 'aminad', 'email': 'aninad@yopmail.com', 'password': 'test1234', 'role': 'product_owner'}
[ERROR] 2025-05-21 13:55:49,837 django - [REGISTER ERROR] Erreur: {'username': [ErrorDetail(string='A user with that username already exists.', code='unique')], 'email': [ErrorDetail(string='user with this email already exists.', code='unique')]}
Traceback (most recent call last):
  File "C:\Users\kone\Documents\socisarl\scrum\apps\users\views.py", line 24, in create
    response = super().create(request, *args, **kwargs)
               ^^^^^^^^^^^^^^^^^^^^^^^^^^^^^^^^^^^^^^^^
  File "C:\Users\kone\Documents\socisarl\scrum\scrumenv\Lib\site-packages\rest_framework\mixins.py", line 18, in create
    serializer.is_valid(raise_exception=True)
  File "C:\Users\kone\Documents\socisarl\scrum\scrumenv\Lib\site-packages\rest_framework\serializers.py", line 233, in is_valid
    raise ValidationError(self.errors)
rest_framework.exceptions.ValidationError: {'username': [ErrorDetail(string='A user with that username already exists.', code='unique')], 'email': [ErrorDetail(string='user with this email already exists.', code='unique')]}
[ERROR] 2025-05-21 13:55:49,959 django.request - Internal Server Error: /api/users/register/
[DEBUG] 2025-05-21 13:55:50,115 urllib3.connectionpool - https://o518522.ingest.us.sentry.io:443 "POST /api/4509357399539712/envelope/ HTTP/1.1" 200 0
[DEBUG] 2025-05-21 13:55:50,354 urllib3.connectionpool - https://o518522.ingest.us.sentry.io:443 "POST /api/4509357399539712/envelope/ HTTP/1.1" 200 0
[DEBUG] 2025-05-21 13:56:23,091 urllib3.connectionpool - https://o518522.ingest.us.sentry.io:443 "POST /api/4509357399539712/envelope/ HTTP/1.1" 200 0
[INFO] 2025-05-21 14:12:37,354 django.utils.autoreload - C:\Users\kone\Documents\socisarl\scrum\config\settings\base.py changed, reloading.
[INFO] 2025-05-21 14:12:56,546 django.utils.autoreload - Watching for file changes with StatReloader
[INFO] 2025-05-21 14:13:08,664 django.utils.autoreload - C:\Users\kone\Documents\socisarl\scrum\config\settings\base.py changed, reloading.
[INFO] 2025-05-21 14:13:41,615 django.utils.autoreload - Watching for file changes with StatReloader
[INFO] 2025-05-21 14:13:48,186 django - [REGISTER] Tentative de création: {'username': 'aminad', 'email': 'aninad@yopmail.com', 'password': 'test1234', 'role': 'product_owner'}
[ERROR] 2025-05-21 14:13:48,814 django - [REGISTER ERROR] Erreur: {'username': [ErrorDetail(string='A user with that username already exists.', code='unique')], 'email': [ErrorDetail(string='user with this email already exists.', code='unique')]}
Traceback (most recent call last):
  File "C:\Users\kone\Documents\socisarl\scrum\apps\users\views.py", line 24, in create
    response = super().create(request, *args, **kwargs)
               ^^^^^^^^^^^^^^^^^^^^^^^^^^^^^^^^^^^^^^^^
  File "C:\Users\kone\Documents\socisarl\scrum\scrumenv\Lib\site-packages\rest_framework\mixins.py", line 18, in create
    serializer.is_valid(raise_exception=True)
  File "C:\Users\kone\Documents\socisarl\scrum\scrumenv\Lib\site-packages\rest_framework\serializers.py", line 233, in is_valid
    raise ValidationError(self.errors)
rest_framework.exceptions.ValidationError: {'username': [ErrorDetail(string='A user with that username already exists.', code='unique')], 'email': [ErrorDetail(string='user with this email already exists.', code='unique')]}
[DEBUG] 2025-05-21 14:13:49,863 urllib3.connectionpool - Starting new HTTPS connection (1): o518522.ingest.us.sentry.io:443
[ERROR] 2025-05-21 14:13:49,870 django.request - Internal Server Error: /api/users/register/
[DEBUG] 2025-05-21 14:13:54,180 urllib3.connectionpool - https://o518522.ingest.us.sentry.io:443 "POST /api/4509357399539712/envelope/ HTTP/1.1" 200 0
[DEBUG] 2025-05-21 14:13:54,377 urllib3.connectionpool - https://o518522.ingest.us.sentry.io:443 "POST /api/4509357399539712/envelope/ HTTP/1.1" 200 0
[INFO] 2025-05-21 14:13:59,422 django - [REGISTER] Tentative de création: {'username': 'aminad', 'email': 'anied@yopmail.com', 'password': 'test1234', 'role': 'product_owner'}
[ERROR] 2025-05-21 14:13:59,452 django - [REGISTER ERROR] Erreur: {'username': [ErrorDetail(string='A user with that username already exists.', code='unique')]}
Traceback (most recent call last):
  File "C:\Users\kone\Documents\socisarl\scrum\apps\users\views.py", line 24, in create
    response = super().create(request, *args, **kwargs)
               ^^^^^^^^^^^^^^^^^^^^^^^^^^^^^^^^^^^^^^^^
  File "C:\Users\kone\Documents\socisarl\scrum\scrumenv\Lib\site-packages\rest_framework\mixins.py", line 18, in create
    serializer.is_valid(raise_exception=True)
  File "C:\Users\kone\Documents\socisarl\scrum\scrumenv\Lib\site-packages\rest_framework\serializers.py", line 233, in is_valid
    raise ValidationError(self.errors)
rest_framework.exceptions.ValidationError: {'username': [ErrorDetail(string='A user with that username already exists.', code='unique')]}
[ERROR] 2025-05-21 14:13:59,546 django.request - Internal Server Error: /api/users/register/
[DEBUG] 2025-05-21 14:13:59,704 urllib3.connectionpool - https://o518522.ingest.us.sentry.io:443 "POST /api/4509357399539712/envelope/ HTTP/1.1" 200 0
[DEBUG] 2025-05-21 14:13:59,889 urllib3.connectionpool - https://o518522.ingest.us.sentry.io:443 "POST /api/4509357399539712/envelope/ HTTP/1.1" 200 0
[DEBUG] 2025-05-21 14:14:10,001 urllib3.connectionpool - https://o518522.ingest.us.sentry.io:443 "POST /api/4509357399539712/envelope/ HTTP/1.1" 200 0
[ERROR] 2025-05-21 14:14:10,979 django.request - Internal Server Error: /api/users/login/
Traceback (most recent call last):
  File "C:\Users\kone\Documents\socisarl\scrum\scrumenv\Lib\site-packages\rest_framework\views.py", line 512, in dispatch
    response = handler(request, *args, **kwargs)
               ^^^^^^^^^^^^^^^^^^^^^^^^^^^^^^^^^
  File "C:\Users\kone\Documents\socisarl\scrum\scrumenv\Lib\site-packages\rest_framework_simplejwt\views.py", line 44, in post
    serializer.is_valid(raise_exception=True)
  File "C:\Users\kone\Documents\socisarl\scrum\scrumenv\Lib\site-packages\rest_framework\serializers.py", line 225, in is_valid
    self._validated_data = self.run_validation(self.initial_data)
                           ^^^^^^^^^^^^^^^^^^^^^^^^^^^^^^^^^^^^^^
  File "C:\Users\kone\Documents\socisarl\scrum\scrumenv\Lib\site-packages\rest_framework\serializers.py", line 447, in run_validation
    value = self.validate(value)
            ^^^^^^^^^^^^^^^^^^^^
  File "C:\Users\kone\Documents\socisarl\scrum\scrumenv\Lib\site-packages\rest_framework_simplejwt\serializers.py", line 73, in validate
    data = super().validate(attrs)
           ^^^^^^^^^^^^^^^^^^^^^^^
  File "C:\Users\kone\Documents\socisarl\scrum\scrumenv\Lib\site-packages\rest_framework_simplejwt\serializers.py", line 57, in validate
    raise exceptions.AuthenticationFailed(
rest_framework.exceptions.AuthenticationFailed: No active account found with the given credentials

During handling of the above exception, another exception occurred:

Traceback (most recent call last):
  File "C:\Users\kone\Documents\socisarl\scrum\scrumenv\Lib\site-packages\rest_framework\settings.py", line 179, in import_from_string
    return import_string(val)
           ^^^^^^^^^^^^^^^^^^
  File "C:\Users\kone\Documents\socisarl\scrum\scrumenv\Lib\site-packages\django\utils\module_loading.py", line 30, in import_string
    return cached_import(module_path, class_name)
           ^^^^^^^^^^^^^^^^^^^^^^^^^^^^^^^^^^^^^^
  File "C:\Users\kone\Documents\socisarl\scrum\scrumenv\Lib\site-packages\django\utils\module_loading.py", line 15, in cached_import
    module = import_module(module_path)
             ^^^^^^^^^^^^^^^^^^^^^^^^^^
  File "C:\Users\kone\AppData\Local\Programs\Python\Python312\Lib\importlib\__init__.py", line 90, in import_module
    return _bootstrap._gcd_import(name[level:], package, level)
           ^^^^^^^^^^^^^^^^^^^^^^^^^^^^^^^^^^^^^^^^^^^^^^^^^^^^
  File "<frozen importlib._bootstrap>", line 1387, in _gcd_import
  File "<frozen importlib._bootstrap>", line 1360, in _find_and_load
  File "<frozen importlib._bootstrap>", line 1324, in _find_and_load_unlocked
ModuleNotFoundError: No module named 'apps.exceptions'

During handling of the above exception, another exception occurred:

Traceback (most recent call last):
  File "C:\Users\kone\Documents\socisarl\scrum\scrumenv\Lib\site-packages\django\core\handlers\exception.py", line 55, in inner
    response = get_response(request)
               ^^^^^^^^^^^^^^^^^^^^^
  File "C:\Users\kone\Documents\socisarl\scrum\scrumenv\Lib\site-packages\django\core\handlers\base.py", line 197, in _get_response
    response = wrapped_callback(request, *callback_args, **callback_kwargs)
               ^^^^^^^^^^^^^^^^^^^^^^^^^^^^^^^^^^^^^^^^^^^^^^^^^^^^^^^^^^^^
  File "C:\Users\kone\Documents\socisarl\scrum\scrumenv\Lib\site-packages\sentry_sdk\integrations\django\views.py", line 94, in sentry_wrapped_callback
    return callback(request, *args, **kwargs)
           ^^^^^^^^^^^^^^^^^^^^^^^^^^^^^^^^^^
  File "C:\Users\kone\Documents\socisarl\scrum\scrumenv\Lib\site-packages\django\views\decorators\csrf.py", line 65, in _view_wrapper
    return view_func(request, *args, **kwargs)
           ^^^^^^^^^^^^^^^^^^^^^^^^^^^^^^^^^^^
  File "C:\Users\kone\Documents\socisarl\scrum\scrumenv\Lib\site-packages\django\views\generic\base.py", line 104, in view
    return self.dispatch(request, *args, **kwargs)
           ^^^^^^^^^^^^^^^^^^^^^^^^^^^^^^^^^^^^^^^
  File "C:\Users\kone\Documents\socisarl\scrum\scrumenv\Lib\site-packages\rest_framework\views.py", line 515, in dispatch
    response = self.handle_exception(exc)
               ^^^^^^^^^^^^^^^^^^^^^^^^^^
  File "C:\Users\kone\Documents\socisarl\scrum\scrumenv\Lib\site-packages\rest_framework\views.py", line 469, in handle_exception
    exception_handler = self.get_exception_handler()
                        ^^^^^^^^^^^^^^^^^^^^^^^^^^^^
  File "C:\Users\kone\Documents\socisarl\scrum\scrumenv\Lib\site-packages\rest_framework\views.py", line 304, in get_exception_handler
    return self.settings.EXCEPTION_HANDLER
           ^^^^^^^^^^^^^^^^^^^^^^^^^^^^^^^
  File "C:\Users\kone\Documents\socisarl\scrum\scrumenv\Lib\site-packages\rest_framework\settings.py", line 227, in __getattr__
    val = perform_import(val, attr)
          ^^^^^^^^^^^^^^^^^^^^^^^^^
  File "C:\Users\kone\Documents\socisarl\scrum\scrumenv\Lib\site-packages\rest_framework\settings.py", line 168, in perform_import
    return import_from_string(val, setting_name)
           ^^^^^^^^^^^^^^^^^^^^^^^^^^^^^^^^^^^^^
  File "C:\Users\kone\Documents\socisarl\scrum\scrumenv\Lib\site-packages\rest_framework\settings.py", line 182, in import_from_string
    raise ImportError(msg)
ImportError: Could not import 'apps.exceptions.custom_exception_handler' for API setting 'EXCEPTION_HANDLER'. ModuleNotFoundError: No module named 'apps.exceptions'.
[DEBUG] 2025-05-21 14:14:11,490 urllib3.connectionpool - https://o518522.ingest.us.sentry.io:443 "POST /api/4509357399539712/envelope/ HTTP/1.1" 200 0
[DEBUG] 2025-05-21 14:14:45,877 urllib3.connectionpool - https://o518522.ingest.us.sentry.io:443 "POST /api/4509357399539712/envelope/ HTTP/1.1" 200 0
[ERROR] 2025-05-21 14:14:45,961 django.request - Internal Server Error: /api/users/users/
Traceback (most recent call last):
  File "C:\Users\kone\Documents\socisarl\scrum\scrumenv\Lib\site-packages\rest_framework\views.py", line 503, in dispatch
    self.initial(request, *args, **kwargs)
  File "C:\Users\kone\Documents\socisarl\scrum\scrumenv\Lib\site-packages\sentry_sdk\integrations\django\__init__.py", line 331, in sentry_patched_drf_initial
    return old_drf_initial(self, request, *args, **kwargs)
           ^^^^^^^^^^^^^^^^^^^^^^^^^^^^^^^^^^^^^^^^^^^^^^^
  File "C:\Users\kone\Documents\socisarl\scrum\scrumenv\Lib\site-packages\rest_framework\views.py", line 420, in initial
    self.perform_authentication(request)
  File "C:\Users\kone\Documents\socisarl\scrum\scrumenv\Lib\site-packages\rest_framework\views.py", line 330, in perform_authentication
    request.user
  File "C:\Users\kone\Documents\socisarl\scrum\scrumenv\Lib\site-packages\rest_framework\request.py", line 232, in user
    self._authenticate()
  File "C:\Users\kone\Documents\socisarl\scrum\scrumenv\Lib\site-packages\rest_framework\request.py", line 385, in _authenticate
    user_auth_tuple = authenticator.authenticate(self)
                      ^^^^^^^^^^^^^^^^^^^^^^^^^^^^^^^^
  File "C:\Users\kone\Documents\socisarl\scrum\scrumenv\Lib\site-packages\rest_framework_simplejwt\authentication.py", line 49, in authenticate
    validated_token = self.get_validated_token(raw_token)
                      ^^^^^^^^^^^^^^^^^^^^^^^^^^^^^^^^^^^
  File "C:\Users\kone\Documents\socisarl\scrum\scrumenv\Lib\site-packages\rest_framework_simplejwt\authentication.py", line 113, in get_validated_token
    raise InvalidToken(
rest_framework_simplejwt.exceptions.InvalidToken: {'detail': ErrorDetail(string='Given token not valid for any token type', code='token_not_valid'), 'code': ErrorDetail(string='token_not_valid', code='token_not_valid'), 'messages': [{'token_class': ErrorDetail(string='AccessToken', code='token_not_valid'), 'token_type': ErrorDetail(string='access', code='token_not_valid'), 'message': ErrorDetail(string='Token is expired', code='token_not_valid')}]}

During handling of the above exception, another exception occurred:

Traceback (most recent call last):
  File "C:\Users\kone\Documents\socisarl\scrum\scrumenv\Lib\site-packages\rest_framework\settings.py", line 179, in import_from_string
    return import_string(val)
           ^^^^^^^^^^^^^^^^^^
  File "C:\Users\kone\Documents\socisarl\scrum\scrumenv\Lib\site-packages\django\utils\module_loading.py", line 30, in import_string
    return cached_import(module_path, class_name)
           ^^^^^^^^^^^^^^^^^^^^^^^^^^^^^^^^^^^^^^
  File "C:\Users\kone\Documents\socisarl\scrum\scrumenv\Lib\site-packages\django\utils\module_loading.py", line 15, in cached_import
    module = import_module(module_path)
             ^^^^^^^^^^^^^^^^^^^^^^^^^^
  File "C:\Users\kone\AppData\Local\Programs\Python\Python312\Lib\importlib\__init__.py", line 90, in import_module
    return _bootstrap._gcd_import(name[level:], package, level)
           ^^^^^^^^^^^^^^^^^^^^^^^^^^^^^^^^^^^^^^^^^^^^^^^^^^^^
  File "<frozen importlib._bootstrap>", line 1387, in _gcd_import
  File "<frozen importlib._bootstrap>", line 1360, in _find_and_load
  File "<frozen importlib._bootstrap>", line 1324, in _find_and_load_unlocked
ModuleNotFoundError: No module named 'apps.exceptions'

During handling of the above exception, another exception occurred:

Traceback (most recent call last):
  File "C:\Users\kone\Documents\socisarl\scrum\scrumenv\Lib\site-packages\django\core\handlers\exception.py", line 55, in inner
    response = get_response(request)
               ^^^^^^^^^^^^^^^^^^^^^
  File "C:\Users\kone\Documents\socisarl\scrum\scrumenv\Lib\site-packages\django\core\handlers\base.py", line 197, in _get_response
    response = wrapped_callback(request, *callback_args, **callback_kwargs)
               ^^^^^^^^^^^^^^^^^^^^^^^^^^^^^^^^^^^^^^^^^^^^^^^^^^^^^^^^^^^^
  File "C:\Users\kone\Documents\socisarl\scrum\scrumenv\Lib\site-packages\sentry_sdk\integrations\django\views.py", line 94, in sentry_wrapped_callback
    return callback(request, *args, **kwargs)
           ^^^^^^^^^^^^^^^^^^^^^^^^^^^^^^^^^^
  File "C:\Users\kone\Documents\socisarl\scrum\scrumenv\Lib\site-packages\django\views\decorators\csrf.py", line 65, in _view_wrapper
    return view_func(request, *args, **kwargs)
           ^^^^^^^^^^^^^^^^^^^^^^^^^^^^^^^^^^^
  File "C:\Users\kone\Documents\socisarl\scrum\scrumenv\Lib\site-packages\django\views\generic\base.py", line 104, in view
    return self.dispatch(request, *args, **kwargs)
           ^^^^^^^^^^^^^^^^^^^^^^^^^^^^^^^^^^^^^^^
  File "C:\Users\kone\Documents\socisarl\scrum\scrumenv\Lib\site-packages\rest_framework\views.py", line 515, in dispatch
    response = self.handle_exception(exc)
               ^^^^^^^^^^^^^^^^^^^^^^^^^^
  File "C:\Users\kone\Documents\socisarl\scrum\scrumenv\Lib\site-packages\rest_framework\views.py", line 469, in handle_exception
    exception_handler = self.get_exception_handler()
                        ^^^^^^^^^^^^^^^^^^^^^^^^^^^^
  File "C:\Users\kone\Documents\socisarl\scrum\scrumenv\Lib\site-packages\rest_framework\views.py", line 304, in get_exception_handler
    return self.settings.EXCEPTION_HANDLER
           ^^^^^^^^^^^^^^^^^^^^^^^^^^^^^^^
  File "C:\Users\kone\Documents\socisarl\scrum\scrumenv\Lib\site-packages\rest_framework\settings.py", line 227, in __getattr__
    val = perform_import(val, attr)
          ^^^^^^^^^^^^^^^^^^^^^^^^^
  File "C:\Users\kone\Documents\socisarl\scrum\scrumenv\Lib\site-packages\rest_framework\settings.py", line 168, in perform_import
    return import_from_string(val, setting_name)
           ^^^^^^^^^^^^^^^^^^^^^^^^^^^^^^^^^^^^^
  File "C:\Users\kone\Documents\socisarl\scrum\scrumenv\Lib\site-packages\rest_framework\settings.py", line 182, in import_from_string
    raise ImportError(msg)
ImportError: Could not import 'apps.exceptions.custom_exception_handler' for API setting 'EXCEPTION_HANDLER'. ModuleNotFoundError: No module named 'apps.exceptions'.
[DEBUG] 2025-05-21 14:14:46,927 urllib3.connectionpool - https://o518522.ingest.us.sentry.io:443 "POST /api/4509357399539712/envelope/ HTTP/1.1" 200 0
[DEBUG] 2025-05-21 14:14:50,839 urllib3.connectionpool - https://o518522.ingest.us.sentry.io:443 "POST /api/4509357399539712/envelope/ HTTP/1.1" 200 0
[INFO] 2025-05-21 14:16:21,554 django.utils.autoreload - C:\Users\kone\Documents\socisarl\scrum\config\settings\base.py changed, reloading.
[INFO] 2025-05-21 14:16:52,772 django.utils.autoreload - Watching for file changes with StatReloader
[DEBUG] 2025-05-21 14:17:00,573 urllib3.connectionpool - Starting new HTTPS connection (1): o518522.ingest.us.sentry.io:443
[ERROR] 2025-05-21 14:17:01,059 django.request - Internal Server Error: /api/users/users/
Traceback (most recent call last):
  File "C:\Users\kone\Documents\socisarl\scrum\scrumenv\Lib\site-packages\rest_framework\views.py", line 503, in dispatch
    self.initial(request, *args, **kwargs)
  File "C:\Users\kone\Documents\socisarl\scrum\scrumenv\Lib\site-packages\sentry_sdk\integrations\django\__init__.py", line 331, in sentry_patched_drf_initial
    return old_drf_initial(self, request, *args, **kwargs)
           ^^^^^^^^^^^^^^^^^^^^^^^^^^^^^^^^^^^^^^^^^^^^^^^
  File "C:\Users\kone\Documents\socisarl\scrum\scrumenv\Lib\site-packages\rest_framework\views.py", line 420, in initial
    self.perform_authentication(request)
  File "C:\Users\kone\Documents\socisarl\scrum\scrumenv\Lib\site-packages\rest_framework\views.py", line 330, in perform_authentication
    request.user
  File "C:\Users\kone\Documents\socisarl\scrum\scrumenv\Lib\site-packages\rest_framework\request.py", line 232, in user
    self._authenticate()
  File "C:\Users\kone\Documents\socisarl\scrum\scrumenv\Lib\site-packages\rest_framework\request.py", line 385, in _authenticate
    user_auth_tuple = authenticator.authenticate(self)
                      ^^^^^^^^^^^^^^^^^^^^^^^^^^^^^^^^
  File "C:\Users\kone\Documents\socisarl\scrum\scrumenv\Lib\site-packages\rest_framework_simplejwt\authentication.py", line 49, in authenticate
    validated_token = self.get_validated_token(raw_token)
                      ^^^^^^^^^^^^^^^^^^^^^^^^^^^^^^^^^^^
  File "C:\Users\kone\Documents\socisarl\scrum\scrumenv\Lib\site-packages\rest_framework_simplejwt\authentication.py", line 113, in get_validated_token
    raise InvalidToken(
rest_framework_simplejwt.exceptions.InvalidToken: {'detail': ErrorDetail(string='Given token not valid for any token type', code='token_not_valid'), 'code': ErrorDetail(string='token_not_valid', code='token_not_valid'), 'messages': [{'token_class': ErrorDetail(string='AccessToken', code='token_not_valid'), 'token_type': ErrorDetail(string='access', code='token_not_valid'), 'message': ErrorDetail(string='Token is expired', code='token_not_valid')}]}

During handling of the above exception, another exception occurred:

Traceback (most recent call last):
  File "C:\Users\kone\Documents\socisarl\scrum\scrumenv\Lib\site-packages\django\utils\module_loading.py", line 30, in import_string
    return cached_import(module_path, class_name)
           ^^^^^^^^^^^^^^^^^^^^^^^^^^^^^^^^^^^^^^
  File "C:\Users\kone\Documents\socisarl\scrum\scrumenv\Lib\site-packages\django\utils\module_loading.py", line 16, in cached_import
    return getattr(module, class_name)
           ^^^^^^^^^^^^^^^^^^^^^^^^^^^
AttributeError: module 'config.exceptions' has no attribute 'custom_exception_handler'

The above exception was the direct cause of the following exception:

Traceback (most recent call last):
  File "C:\Users\kone\Documents\socisarl\scrum\scrumenv\Lib\site-packages\rest_framework\settings.py", line 179, in import_from_string
    return import_string(val)
           ^^^^^^^^^^^^^^^^^^
  File "C:\Users\kone\Documents\socisarl\scrum\scrumenv\Lib\site-packages\django\utils\module_loading.py", line 32, in import_string
    raise ImportError(
ImportError: Module "config.exceptions" does not define a "custom_exception_handler" attribute/class

During handling of the above exception, another exception occurred:

Traceback (most recent call last):
  File "C:\Users\kone\Documents\socisarl\scrum\scrumenv\Lib\site-packages\django\core\handlers\exception.py", line 55, in inner
    response = get_response(request)
               ^^^^^^^^^^^^^^^^^^^^^
  File "C:\Users\kone\Documents\socisarl\scrum\scrumenv\Lib\site-packages\django\core\handlers\base.py", line 197, in _get_response
    response = wrapped_callback(request, *callback_args, **callback_kwargs)
               ^^^^^^^^^^^^^^^^^^^^^^^^^^^^^^^^^^^^^^^^^^^^^^^^^^^^^^^^^^^^
  File "C:\Users\kone\Documents\socisarl\scrum\scrumenv\Lib\site-packages\sentry_sdk\integrations\django\views.py", line 94, in sentry_wrapped_callback
    return callback(request, *args, **kwargs)
           ^^^^^^^^^^^^^^^^^^^^^^^^^^^^^^^^^^
  File "C:\Users\kone\Documents\socisarl\scrum\scrumenv\Lib\site-packages\django\views\decorators\csrf.py", line 65, in _view_wrapper
    return view_func(request, *args, **kwargs)
           ^^^^^^^^^^^^^^^^^^^^^^^^^^^^^^^^^^^
  File "C:\Users\kone\Documents\socisarl\scrum\scrumenv\Lib\site-packages\django\views\generic\base.py", line 104, in view
    return self.dispatch(request, *args, **kwargs)
           ^^^^^^^^^^^^^^^^^^^^^^^^^^^^^^^^^^^^^^^
  File "C:\Users\kone\Documents\socisarl\scrum\scrumenv\Lib\site-packages\rest_framework\views.py", line 515, in dispatch
    response = self.handle_exception(exc)
               ^^^^^^^^^^^^^^^^^^^^^^^^^^
  File "C:\Users\kone\Documents\socisarl\scrum\scrumenv\Lib\site-packages\rest_framework\views.py", line 469, in handle_exception
    exception_handler = self.get_exception_handler()
                        ^^^^^^^^^^^^^^^^^^^^^^^^^^^^
  File "C:\Users\kone\Documents\socisarl\scrum\scrumenv\Lib\site-packages\rest_framework\views.py", line 304, in get_exception_handler
    return self.settings.EXCEPTION_HANDLER
           ^^^^^^^^^^^^^^^^^^^^^^^^^^^^^^^
  File "C:\Users\kone\Documents\socisarl\scrum\scrumenv\Lib\site-packages\rest_framework\settings.py", line 227, in __getattr__
    val = perform_import(val, attr)
          ^^^^^^^^^^^^^^^^^^^^^^^^^
  File "C:\Users\kone\Documents\socisarl\scrum\scrumenv\Lib\site-packages\rest_framework\settings.py", line 168, in perform_import
    return import_from_string(val, setting_name)
           ^^^^^^^^^^^^^^^^^^^^^^^^^^^^^^^^^^^^^
  File "C:\Users\kone\Documents\socisarl\scrum\scrumenv\Lib\site-packages\rest_framework\settings.py", line 182, in import_from_string
    raise ImportError(msg)
ImportError: Could not import 'config.exceptions.custom_exception_handler' for API setting 'EXCEPTION_HANDLER'. ImportError: Module "config.exceptions" does not define a "custom_exception_handler" attribute/class.
[DEBUG] 2025-05-21 14:17:04,069 urllib3.connectionpool - https://o518522.ingest.us.sentry.io:443 "POST /api/4509357399539712/envelope/ HTTP/1.1" 200 0
[DEBUG] 2025-05-21 14:17:04,315 urllib3.connectionpool - https://o518522.ingest.us.sentry.io:443 "POST /api/4509357399539712/envelope/ HTTP/1.1" 200 0
[DEBUG] 2025-05-21 14:17:57,185 urllib3.connectionpool - https://o518522.ingest.us.sentry.io:443 "POST /api/4509357399539712/envelope/ HTTP/1.1" 200 0
[ERROR] 2025-05-21 14:17:57,243 django.request - Internal Server Error: /api/users/login/
Traceback (most recent call last):
  File "C:\Users\kone\Documents\socisarl\scrum\scrumenv\Lib\site-packages\rest_framework\views.py", line 512, in dispatch
    response = handler(request, *args, **kwargs)
               ^^^^^^^^^^^^^^^^^^^^^^^^^^^^^^^^^
  File "C:\Users\kone\Documents\socisarl\scrum\scrumenv\Lib\site-packages\rest_framework_simplejwt\views.py", line 44, in post
    serializer.is_valid(raise_exception=True)
  File "C:\Users\kone\Documents\socisarl\scrum\scrumenv\Lib\site-packages\rest_framework\serializers.py", line 225, in is_valid
    self._validated_data = self.run_validation(self.initial_data)
                           ^^^^^^^^^^^^^^^^^^^^^^^^^^^^^^^^^^^^^^
  File "C:\Users\kone\Documents\socisarl\scrum\scrumenv\Lib\site-packages\rest_framework\serializers.py", line 447, in run_validation
    value = self.validate(value)
            ^^^^^^^^^^^^^^^^^^^^
  File "C:\Users\kone\Documents\socisarl\scrum\scrumenv\Lib\site-packages\rest_framework_simplejwt\serializers.py", line 73, in validate
    data = super().validate(attrs)
           ^^^^^^^^^^^^^^^^^^^^^^^
  File "C:\Users\kone\Documents\socisarl\scrum\scrumenv\Lib\site-packages\rest_framework_simplejwt\serializers.py", line 57, in validate
    raise exceptions.AuthenticationFailed(
rest_framework.exceptions.AuthenticationFailed: No active account found with the given credentials

During handling of the above exception, another exception occurred:

Traceback (most recent call last):
  File "C:\Users\kone\Documents\socisarl\scrum\scrumenv\Lib\site-packages\django\utils\module_loading.py", line 30, in import_string
    return cached_import(module_path, class_name)
           ^^^^^^^^^^^^^^^^^^^^^^^^^^^^^^^^^^^^^^
  File "C:\Users\kone\Documents\socisarl\scrum\scrumenv\Lib\site-packages\django\utils\module_loading.py", line 16, in cached_import
    return getattr(module, class_name)
           ^^^^^^^^^^^^^^^^^^^^^^^^^^^
AttributeError: module 'config.exceptions' has no attribute 'custom_exception_handler'

The above exception was the direct cause of the following exception:

Traceback (most recent call last):
  File "C:\Users\kone\Documents\socisarl\scrum\scrumenv\Lib\site-packages\rest_framework\settings.py", line 179, in import_from_string
    return import_string(val)
           ^^^^^^^^^^^^^^^^^^
  File "C:\Users\kone\Documents\socisarl\scrum\scrumenv\Lib\site-packages\django\utils\module_loading.py", line 32, in import_string
    raise ImportError(
ImportError: Module "config.exceptions" does not define a "custom_exception_handler" attribute/class

During handling of the above exception, another exception occurred:

Traceback (most recent call last):
  File "C:\Users\kone\Documents\socisarl\scrum\scrumenv\Lib\site-packages\django\core\handlers\exception.py", line 55, in inner
    response = get_response(request)
               ^^^^^^^^^^^^^^^^^^^^^
  File "C:\Users\kone\Documents\socisarl\scrum\scrumenv\Lib\site-packages\django\core\handlers\base.py", line 197, in _get_response
    response = wrapped_callback(request, *callback_args, **callback_kwargs)
               ^^^^^^^^^^^^^^^^^^^^^^^^^^^^^^^^^^^^^^^^^^^^^^^^^^^^^^^^^^^^
  File "C:\Users\kone\Documents\socisarl\scrum\scrumenv\Lib\site-packages\sentry_sdk\integrations\django\views.py", line 94, in sentry_wrapped_callback
    return callback(request, *args, **kwargs)
           ^^^^^^^^^^^^^^^^^^^^^^^^^^^^^^^^^^
  File "C:\Users\kone\Documents\socisarl\scrum\scrumenv\Lib\site-packages\django\views\decorators\csrf.py", line 65, in _view_wrapper
    return view_func(request, *args, **kwargs)
           ^^^^^^^^^^^^^^^^^^^^^^^^^^^^^^^^^^^
  File "C:\Users\kone\Documents\socisarl\scrum\scrumenv\Lib\site-packages\django\views\generic\base.py", line 104, in view
    return self.dispatch(request, *args, **kwargs)
           ^^^^^^^^^^^^^^^^^^^^^^^^^^^^^^^^^^^^^^^
  File "C:\Users\kone\Documents\socisarl\scrum\scrumenv\Lib\site-packages\rest_framework\views.py", line 515, in dispatch
    response = self.handle_exception(exc)
               ^^^^^^^^^^^^^^^^^^^^^^^^^^
  File "C:\Users\kone\Documents\socisarl\scrum\scrumenv\Lib\site-packages\rest_framework\views.py", line 469, in handle_exception
    exception_handler = self.get_exception_handler()
                        ^^^^^^^^^^^^^^^^^^^^^^^^^^^^
  File "C:\Users\kone\Documents\socisarl\scrum\scrumenv\Lib\site-packages\rest_framework\views.py", line 304, in get_exception_handler
    return self.settings.EXCEPTION_HANDLER
           ^^^^^^^^^^^^^^^^^^^^^^^^^^^^^^^
  File "C:\Users\kone\Documents\socisarl\scrum\scrumenv\Lib\site-packages\rest_framework\settings.py", line 227, in __getattr__
    val = perform_import(val, attr)
          ^^^^^^^^^^^^^^^^^^^^^^^^^
  File "C:\Users\kone\Documents\socisarl\scrum\scrumenv\Lib\site-packages\rest_framework\settings.py", line 168, in perform_import
    return import_from_string(val, setting_name)
           ^^^^^^^^^^^^^^^^^^^^^^^^^^^^^^^^^^^^^
  File "C:\Users\kone\Documents\socisarl\scrum\scrumenv\Lib\site-packages\rest_framework\settings.py", line 182, in import_from_string
    raise ImportError(msg)
ImportError: Could not import 'config.exceptions.custom_exception_handler' for API setting 'EXCEPTION_HANDLER'. ImportError: Module "config.exceptions" does not define a "custom_exception_handler" attribute/class.
[DEBUG] 2025-05-21 14:17:58,188 urllib3.connectionpool - https://o518522.ingest.us.sentry.io:443 "POST /api/4509357399539712/envelope/ HTTP/1.1" 200 0
[DEBUG] 2025-05-21 14:18:02,224 urllib3.connectionpool - https://o518522.ingest.us.sentry.io:443 "POST /api/4509357399539712/envelope/ HTTP/1.1" 200 0
[INFO] 2025-05-21 14:19:07,344 django.utils.autoreload - C:\Users\kone\Documents\socisarl\scrum\config\settings\base.py changed, reloading.
[INFO] 2025-05-21 14:19:24,828 django.utils.autoreload - Watching for file changes with StatReloader
[DEBUG] 2025-05-21 14:19:32,230 urllib3.connectionpool - Starting new HTTPS connection (1): o518522.ingest.us.sentry.io:443
[ERROR] 2025-05-21 14:19:32,547 django.request - Internal Server Error: /api/users/users/
Traceback (most recent call last):
  File "C:\Users\kone\Documents\socisarl\scrum\scrumenv\Lib\site-packages\rest_framework\views.py", line 503, in dispatch
    self.initial(request, *args, **kwargs)
  File "C:\Users\kone\Documents\socisarl\scrum\scrumenv\Lib\site-packages\sentry_sdk\integrations\django\__init__.py", line 331, in sentry_patched_drf_initial
    return old_drf_initial(self, request, *args, **kwargs)
           ^^^^^^^^^^^^^^^^^^^^^^^^^^^^^^^^^^^^^^^^^^^^^^^
  File "C:\Users\kone\Documents\socisarl\scrum\scrumenv\Lib\site-packages\rest_framework\views.py", line 420, in initial
    self.perform_authentication(request)
  File "C:\Users\kone\Documents\socisarl\scrum\scrumenv\Lib\site-packages\rest_framework\views.py", line 330, in perform_authentication
    request.user
  File "C:\Users\kone\Documents\socisarl\scrum\scrumenv\Lib\site-packages\rest_framework\request.py", line 232, in user
    self._authenticate()
  File "C:\Users\kone\Documents\socisarl\scrum\scrumenv\Lib\site-packages\rest_framework\request.py", line 385, in _authenticate
    user_auth_tuple = authenticator.authenticate(self)
                      ^^^^^^^^^^^^^^^^^^^^^^^^^^^^^^^^
  File "C:\Users\kone\Documents\socisarl\scrum\scrumenv\Lib\site-packages\rest_framework_simplejwt\authentication.py", line 49, in authenticate
    validated_token = self.get_validated_token(raw_token)
                      ^^^^^^^^^^^^^^^^^^^^^^^^^^^^^^^^^^^
  File "C:\Users\kone\Documents\socisarl\scrum\scrumenv\Lib\site-packages\rest_framework_simplejwt\authentication.py", line 113, in get_validated_token
    raise InvalidToken(
rest_framework_simplejwt.exceptions.InvalidToken: {'detail': ErrorDetail(string='Given token not valid for any token type', code='token_not_valid'), 'code': ErrorDetail(string='token_not_valid', code='token_not_valid'), 'messages': [{'token_class': ErrorDetail(string='AccessToken', code='token_not_valid'), 'token_type': ErrorDetail(string='access', code='token_not_valid'), 'message': ErrorDetail(string='Token is expired', code='token_not_valid')}]}

During handling of the above exception, another exception occurred:

Traceback (most recent call last):
  File "C:\Users\kone\Documents\socisarl\scrum\scrumenv\Lib\site-packages\rest_framework\settings.py", line 179, in import_from_string
    return import_string(val)
           ^^^^^^^^^^^^^^^^^^
  File "C:\Users\kone\Documents\socisarl\scrum\scrumenv\Lib\site-packages\django\utils\module_loading.py", line 30, in import_string
    return cached_import(module_path, class_name)
           ^^^^^^^^^^^^^^^^^^^^^^^^^^^^^^^^^^^^^^
  File "C:\Users\kone\Documents\socisarl\scrum\scrumenv\Lib\site-packages\django\utils\module_loading.py", line 15, in cached_import
    module = import_module(module_path)
             ^^^^^^^^^^^^^^^^^^^^^^^^^^
  File "C:\Users\kone\AppData\Local\Programs\Python\Python312\Lib\importlib\__init__.py", line 90, in import_module
    return _bootstrap._gcd_import(name[level:], package, level)
           ^^^^^^^^^^^^^^^^^^^^^^^^^^^^^^^^^^^^^^^^^^^^^^^^^^^^
  File "<frozen importlib._bootstrap>", line 1387, in _gcd_import
  File "<frozen importlib._bootstrap>", line 1360, in _find_and_load
  File "<frozen importlib._bootstrap>", line 1324, in _find_and_load_unlocked
ModuleNotFoundError: No module named 'config.exceptions.exception'

During handling of the above exception, another exception occurred:

Traceback (most recent call last):
  File "C:\Users\kone\Documents\socisarl\scrum\scrumenv\Lib\site-packages\django\core\handlers\exception.py", line 55, in inner
    response = get_response(request)
               ^^^^^^^^^^^^^^^^^^^^^
  File "C:\Users\kone\Documents\socisarl\scrum\scrumenv\Lib\site-packages\django\core\handlers\base.py", line 197, in _get_response
    response = wrapped_callback(request, *callback_args, **callback_kwargs)
               ^^^^^^^^^^^^^^^^^^^^^^^^^^^^^^^^^^^^^^^^^^^^^^^^^^^^^^^^^^^^
  File "C:\Users\kone\Documents\socisarl\scrum\scrumenv\Lib\site-packages\sentry_sdk\integrations\django\views.py", line 94, in sentry_wrapped_callback
    return callback(request, *args, **kwargs)
           ^^^^^^^^^^^^^^^^^^^^^^^^^^^^^^^^^^
  File "C:\Users\kone\Documents\socisarl\scrum\scrumenv\Lib\site-packages\django\views\decorators\csrf.py", line 65, in _view_wrapper
    return view_func(request, *args, **kwargs)
           ^^^^^^^^^^^^^^^^^^^^^^^^^^^^^^^^^^^
  File "C:\Users\kone\Documents\socisarl\scrum\scrumenv\Lib\site-packages\django\views\generic\base.py", line 104, in view
    return self.dispatch(request, *args, **kwargs)
           ^^^^^^^^^^^^^^^^^^^^^^^^^^^^^^^^^^^^^^^
  File "C:\Users\kone\Documents\socisarl\scrum\scrumenv\Lib\site-packages\rest_framework\views.py", line 515, in dispatch
    response = self.handle_exception(exc)
               ^^^^^^^^^^^^^^^^^^^^^^^^^^
  File "C:\Users\kone\Documents\socisarl\scrum\scrumenv\Lib\site-packages\rest_framework\views.py", line 469, in handle_exception
    exception_handler = self.get_exception_handler()
                        ^^^^^^^^^^^^^^^^^^^^^^^^^^^^
  File "C:\Users\kone\Documents\socisarl\scrum\scrumenv\Lib\site-packages\rest_framework\views.py", line 304, in get_exception_handler
    return self.settings.EXCEPTION_HANDLER
           ^^^^^^^^^^^^^^^^^^^^^^^^^^^^^^^
  File "C:\Users\kone\Documents\socisarl\scrum\scrumenv\Lib\site-packages\rest_framework\settings.py", line 227, in __getattr__
    val = perform_import(val, attr)
          ^^^^^^^^^^^^^^^^^^^^^^^^^
  File "C:\Users\kone\Documents\socisarl\scrum\scrumenv\Lib\site-packages\rest_framework\settings.py", line 168, in perform_import
    return import_from_string(val, setting_name)
           ^^^^^^^^^^^^^^^^^^^^^^^^^^^^^^^^^^^^^
  File "C:\Users\kone\Documents\socisarl\scrum\scrumenv\Lib\site-packages\rest_framework\settings.py", line 182, in import_from_string
    raise ImportError(msg)
ImportError: Could not import 'config.exceptions.exception.custom_exception_handler' for API setting 'EXCEPTION_HANDLER'. ModuleNotFoundError: No module named 'config.exceptions.exception'.
[DEBUG] 2025-05-21 14:19:36,687 urllib3.connectionpool - https://o518522.ingest.us.sentry.io:443 "POST /api/4509357399539712/envelope/ HTTP/1.1" 200 0
[DEBUG] 2025-05-21 14:19:36,964 urllib3.connectionpool - https://o518522.ingest.us.sentry.io:443 "POST /api/4509357399539712/envelope/ HTTP/1.1" 200 0
[INFO] 2025-05-21 14:19:52,838 django.utils.autoreload - C:\Users\kone\Documents\socisarl\scrum\config\settings\base.py changed, reloading.
[DEBUG] 2025-05-21 14:19:53,238 urllib3.connectionpool - https://o518522.ingest.us.sentry.io:443 "POST /api/4509357399539712/envelope/ HTTP/1.1" 200 0
[INFO] 2025-05-21 14:20:10,790 django.utils.autoreload - Watching for file changes with StatReloader
[DEBUG] 2025-05-21 14:20:17,801 urllib3.connectionpool - Starting new HTTPS connection (1): o518522.ingest.us.sentry.io:443
[WARNING] 2025-05-21 14:20:17,796 django.request - Unauthorized: /api/users/users/
[DEBUG] 2025-05-21 14:20:19,835 urllib3.connectionpool - https://o518522.ingest.us.sentry.io:443 "POST /api/4509357399539712/envelope/ HTTP/1.1" 200 0
[DEBUG] 2025-05-21 14:20:19,958 urllib3.connectionpool - https://o518522.ingest.us.sentry.io:443 "POST /api/4509357399539712/envelope/ HTTP/1.1" 200 0
[DEBUG] 2025-05-21 14:21:18,069 urllib3.connectionpool - https://o518522.ingest.us.sentry.io:443 "POST /api/4509357399539712/envelope/ HTTP/1.1" 200 0
[INFO] 2025-05-21 14:29:47,402 django.utils.autoreload - C:\Users\kone\Documents\socisarl\scrum\config\settings\base.py changed, reloading.
[INFO] 2025-05-21 14:30:03,690 django.utils.autoreload - Watching for file changes with StatReloader
[INFO] 2025-05-21 16:06:47,500 django.utils.autoreload - C:\Users\kone\Documents\socisarl\scrum\apps\users\views.py changed, reloading.
[INFO] 2025-05-21 16:07:03,134 django.utils.autoreload - Watching for file changes with StatReloader
[INFO] 2025-05-21 16:07:27,468 django.utils.autoreload - C:\Users\kone\Documents\socisarl\scrum\apps\users\views.py changed, reloading.
[INFO] 2025-05-21 16:07:40,308 django.utils.autoreload - Watching for file changes with StatReloader
[WARNING] 2025-05-21 16:08:05,129 django.request - Unauthorized: /api/users/users/
[DEBUG] 2025-05-21 16:08:05,148 urllib3.connectionpool - Starting new HTTPS connection (1): o518522.ingest.us.sentry.io:443
[DEBUG] 2025-05-21 16:08:08,440 urllib3.connectionpool - https://o518522.ingest.us.sentry.io:443 "POST /api/4509357399539712/envelope/ HTTP/1.1" 200 0
[DEBUG] 2025-05-21 16:08:08,563 urllib3.connectionpool - https://o518522.ingest.us.sentry.io:443 "POST /api/4509357399539712/envelope/ HTTP/1.1" 200 0
[WARNING] 2025-05-21 16:08:34,063 django.request - Unauthorized: /api/users/login/
[DEBUG] 2025-05-21 16:08:34,248 urllib3.connectionpool - https://o518522.ingest.us.sentry.io:443 "POST /api/4509357399539712/envelope/ HTTP/1.1" 200 0
[DEBUG] 2025-05-21 16:08:35,451 urllib3.connectionpool - https://o518522.ingest.us.sentry.io:443 "POST /api/4509357399539712/envelope/ HTTP/1.1" 200 0
[DEBUG] 2025-05-21 16:09:05,868 urllib3.connectionpool - https://o518522.ingest.us.sentry.io:443 "POST /api/4509357399539712/envelope/ HTTP/1.1" 200 0
[INFO] 2025-05-21 17:15:54,021 django.utils.autoreload - C:\Users\kone\Documents\socisarl\scrum\apps\users\views.py changed, reloading.
[INFO] 2025-05-21 17:16:09,240 django.utils.autoreload - Watching for file changes with StatReloader
[INFO] 2025-05-21 17:16:21,089 django.utils.autoreload - C:\Users\kone\Documents\socisarl\scrum\apps\users\views.py changed, reloading.
[INFO] 2025-05-21 17:16:29,302 django.utils.autoreload - Watching for file changes with StatReloader
